<?xml version = "1.0"?>

<robot name="lf_bot" xmlns:xacro ="https://www.ros.org/wiki/xacro">

<xacro:include filename="$(find line_follwer)/urdf/material.xacro"/>
<xacro:include filename="$(find line_follwer)/urdf/bot.gazebo"/>

  <link name = "base_link">

    <inertial>
      <mass value="5"/>
      <origin xyz="0 0 0.1" rpy="0 0 0"/>
      <inertia ixx="0.0395416666667" ixy="0" ixz="0" iyy="0.106208333333" iyz="0" izz="0.106208333333"/>
    </inertial>

    <collision name="base">
      <origin xyz="0 0 0" rpy="0 0 0"/>
      <geometry>
        <box size = "0.5 0.3 0.07"/>
      </geometry>
    </collision>

    <visual name="base_visual">
      <origin xyz="0 0 0" rpy="0 0 0"/>
      <geometry>
        <box size="0.5 0.3 0.07"/>
      </geometry>
      <material name="red"/>
    </visual>

    <collision name="caster_front_collision">
      <origin rpy=" 0 0 0" xyz="0.35 0 -0.05"/>
      <geometry>
        <sphere radius="0.05"/>
      </geometry>
      <surface>
        <friction>
          <ode>
            <mu>0</mu>
            <mu2>0</mu2>
            <slip1>1.0</slip1>
            <slip2>1.0</slip2>
          </ode>
        </friction>
      </surface>
    </collision>

    <visual name="caster_front_visual">
      <origin rpy=" 0 0 0" xyz="0.2 0 -0.05"/>
      <geometry>
        <sphere radius="0.05"/>
      </geometry>
    </visual>

  </link>

  <link name="link_right_wheel">
    <inertial>
      <mass value="0.2"/>
      <origin rpy="0 1.5707 1.5707" xyz="0 0 0"/>
      <inertia ixx="0.00052666666" ixy="0" ixz="0" iyy="0.00052666666" iyz="0" izz="0.001"/>
    </inertial>

    <collision name="link_right_wheel_collision">
      <origin rpy="0 1.5707 1.5707" xyz="0 0 0" />
      <geometry>
        <cylinder length="0.04" radius="0.1"/>
      </geometry>
    </collision>

    <visual name="link_right_wheel_visual">
      <origin rpy="0 1.5707 1.5707" xyz="0 0 0"/>
      <geometry>
        <cylinder length="0.04" radius="0.1"/>
      </geometry>
      <material name="blue"/>
    </visual>

  </link>

  <link name="link_left_wheel">
    <inertial>
      <mass value="0.2"/>
      <origin rpy="0 1.5707 1.5707" xyz="0 0 0"/>
      <inertia ixx="0.00052666666" ixy="0" ixz="0" iyy="0.00052666666" iyz="0" izz="0.001"/>
    </inertial>

    <collision name="link_left_wheel_collision">
      <origin rpy="0 1.5707 1.5707" xyz="0 0 0" />
      <geometry>
        <cylinder length="0.04" radius="0.1"/>
      </geometry>
    </collision>

    <visual name="link_left_wheel_visual">
      <origin rpy="0 1.5707 1.5707" xyz="0 0 0"/>
      <geometry>
        <cylinder length="0.04" radius="0.1"/>
      </geometry>
      <material name="blue"/>
    </visual>

  </link>

  <joint name="joint_right_wheel" type="continuous">
   <origin rpy="0 0 0" xyz="-0.05 0.15 0"/>
   <child link="link_right_wheel" />
   <parent link="base_link"/>
   <axis rpy="0 0 0" xyz="0 1 0"/>
  </joint>

  <joint name="joint_left_wheel" type="continuous">
    <origin rpy="0 0 0" xyz="-0.05 -0.15 0"/>
    <child link="link_left_wheel" />
    <parent link="base_link"/>
    <axis rpy="0 0 0" xyz="0 1 0"/>
 </joint>


 <link name ="camera_link">
   <inertial>
     <mass value="0.01"/>
     <orgin rpy="0 0 0" xyz="0 0 0"/>
     <inertia ixx="0.0000001" ixy="0" ixz="0" iyy="0.0000001" iyz="0" izz="0.0000001"/>
  </inertial>

  <collision>
    <origin rpy="0 0 0" xyz="0 0 0"/>
    <geometry>
      <box size="0.001 0.001 0.001"/>
    </geometry>
  </collision>

  <visual>
    <orgin xyz="0 0 0" rpy="0 0 0"/>
    <geometry>
      <box size="0.01 0.05 0.05"/>
    </geometry>
    <material name="green"/>
  </visual>
</link>

<joint name="camera_base_joint" type="fixed">
  <origin rpy="0 0 0" xyz="0.25 0 0"/>
  <child link="camera_link"/>
  <parent link="base_link"/>
</joint>

</robot>
